<?xml version="1.0" encoding="UTF-8"?>
<!-- Generated by org.testng.reporters.JUnitReportReporter -->
<testsuite hostname="desktop1" failures="1" tests="6" name="api.test.UserTests" time="7.509" errors="0" timestamp="2024-07-15T16:46:04 BDT" skipped="3">
  <testcase classname="api.test.UserTests" name="test_CreateUser" time="3.826">
    <failure message="message should contain ok message expected [true] but found [false]" type="java.lang.AssertionError">
      <![CDATA[java.lang.AssertionError: message should contain ok message expected [true] but found [false]
at org.testng.Assert.fail(Assert.java:99)
at org.testng.Assert.failNotEquals(Assert.java:1037)
at org.testng.Assert.assertTrue(Assert.java:45)
at api.test.UserTests.test_CreateUser(UserTests.java:34)
at java.base/jdk.internal.reflect.NativeMethodAccessorImpl.invoke0(Native Method)
at java.base/jdk.internal.reflect.NativeMethodAccessorImpl.invoke(NativeMethodAccessorImpl.java:77)
at java.base/jdk.internal.reflect.DelegatingMethodAccessorImpl.invoke(DelegatingMethodAccessorImpl.java:43)
at java.base/java.lang.reflect.Method.invoke(Method.java:568)
at org.testng.internal.MethodInvocationHelper.invokeMethod(MethodInvocationHelper.java:133)
at org.testng.internal.TestInvoker.invokeMethod(TestInvoker.java:598)
at org.testng.internal.TestInvoker.invokeTestMethod(TestInvoker.java:173)
at org.testng.internal.MethodRunner.runInSequence(MethodRunner.java:46)
at org.testng.internal.TestInvoker$MethodInvocationAgent.invoke(TestInvoker.java:824)
at org.testng.internal.TestInvoker.invokeTestMethods(TestInvoker.java:146)
at org.testng.internal.TestMethodWorker.invokeTestMethods(TestMethodWorker.java:146)
at org.testng.internal.TestMethodWorker.run(TestMethodWorker.java:128)
at java.base/java.util.ArrayList.forEach(ArrayList.java:1511)
at org.testng.TestRunner.privateRun(TestRunner.java:794)
at org.testng.TestRunner.run(TestRunner.java:596)
at org.testng.SuiteRunner.runTest(SuiteRunner.java:377)
at org.testng.SuiteRunner.runSequentially(SuiteRunner.java:371)
at org.testng.SuiteRunner.privateRun(SuiteRunner.java:332)
at org.testng.SuiteRunner.run(SuiteRunner.java:276)
at org.testng.SuiteRunnerWorker.runSuite(SuiteRunnerWorker.java:53)
at org.testng.SuiteRunnerWorker.run(SuiteRunnerWorker.java:96)
at org.testng.TestNG.runSuitesSequentially(TestNG.java:1212)
at org.testng.TestNG.runSuitesLocally(TestNG.java:1134)
at org.testng.TestNG.runSuites(TestNG.java:1063)
at org.testng.TestNG.run(TestNG.java:1031)
at org.testng.remote.AbstractRemoteTestNG.run(AbstractRemoteTestNG.java:115)
at org.testng.remote.RemoteTestNG.initAndRun(RemoteTestNG.java:293)
at org.testng.remote.RemoteTestNG.main(RemoteTestNG.java:91)
]]>
    </failure>
  </testcase> <!-- test_CreateUser -->
  <system-out/>
  <testcase classname="api.test.UserTests" name="test_GetUser" time="0.000">
    <skipped/>
  </testcase> <!-- test_GetUser -->
  <system-out/>
  <testcase classname="api.test.UserTests" name="test_LoginUser" time="1.365"/>
  <system-out/>
  <testcase classname="api.test.UserTests" name="test_LogoutUser" time="2.318"/>
  <system-out/>
  <testcase classname="api.test.UserTests" name="test_UpdateUser" time="0.000">
    <skipped/>
  </testcase> <!-- test_UpdateUser -->
  <system-out/>
  <testcase classname="api.test.UserTests" name="test_DeleteUser" time="0.000">
    <skipped/>
  </testcase> <!-- test_DeleteUser -->
  <system-out/>
</testsuite> <!-- api.test.UserTests -->
